Workbook

Sheet Drivers
A1: Car # | B1: Driver | C1: Race 01 | D1: Race 02 | E1: Race 03 | F1: Race 04 | G1: Race 05 | H1: Race 06 | I1: Race 07 | J1: Race 08 | K1: Race 09 | L1: Race 10 | M1: Race 11 | N1: Race 12 | O1: Race 13 | P1: Race 14 | Q1: Race 15 | R1: Race 16 | S1: Race 17 | T1: Race 18 | U1: Race 19 | V1: Race 20 | W1: Race 21 | X1: Race 22 | Y1: Race 23 | Z1: Race 24 | AA1: Race 25 | AB1: Race 26 | AC1: Race 27 | AD1: Race 28 | AE1: Race 29 | AF1: Race 30 | AG1: Race 31 | AH1: Race 32 | AI1: Race 33 | AJ1: Race 34 | AK1: Race 35 | AL1: Race 36 | AM1: Total
AN2: Red League | AQ2: White League | AT2: Blue League
AN3: Owner | AO3: Drivers | AQ3: Owner | AR3: Drivers | AT3: Owner | AU3: Drivers
A4: 1 | B4: R. Chastain | C4: 17 | D4: 34 | E4: 13 | F4: 10 | G4: 20 | H4: 21 | I4: 21 | J4: 17 | K4: 11 | L4: 41 | M4: 11 | N4: 20 | O4: 2 | P4: 1 | Q4: 21 | R4: 34 | S4: 33 | T4: 29 | U4: 19 | V4: 26 | W4: 11 | X4: 24 | Y4: 43 | Z4: 25 | AA4: 1 | AB4: 13 | AM4: =SUM(C4:AL4) -> 518 | AN4: Dehaven | AO4: Elliott | AQ4: Dustin | AR4: Briscoe | AT4: Carole | AU4: Elliott
A5: 2 | B5: A. Cindric | C5: 12 | D5: 21 | E5: 5 | F5: 13 | G5: 19 | H5: 38 | I5: 40 | J5: 23 | K5: 25 | L5: 29 | M5: 22 | N5: 39 | O5: 1 | P5: 18 | Q5: 26 | R5: 23 | S5: 15 | T5: 31 | U5: 33 | V5: 36 | W5: 25 | X5: 23 | Y5: 8 | Z5: 48 | AA5: 25 | AB5: 32 | AM5: =SUM(C5:AL5) -> 630 | AO5: Reddick | AR5: Logano | AU5: Reddick
A6: 3 | B6: A. Dillon | Y6: 33 | Z6: 18 | AA6: 5 | AB6: 30 | AM6: =SUM(C6:AL6) -> 86
A7: 4 | B7: N. Gragson | Y7: 20 | Z7: 19 | AA7: 27 | AB7: 12 | AM7: =SUM(C7:AL7) -> 78 | AN7: Gehman (1) | AO7: Byron | AQ7: Derrick | AR7: Bell | AT7: Butch | AU7: Briscoe
A8: 5 | B8: K. Larson | C8: 21 | D8: 13 | E8: 31 | F8: 36 | G8: 48 | H8: 19 | I8: 30 | J8: 54 | K8: 54 | L8: 1 | M8: 3 | N8: 14 | O8: 54 | P8: 23 | Q8: 44 | R8: 24 | S8: 42 | T8: 35 | U8: 12 | V8: 11 | W8: 22 | X8: 1 | Y8: 12 | Z8: 31 | AA8: 48 | AB8: 16 | AM8: =SUM(C8:AL8) -> 699 | AO8: Logano | AR8: Buscher | AU8: Van Gisbergen
A9: 6 | B9: B. Kezelowski | H9: 55 | I9: 24 | J9: 23 | K9: 35 | L9: 15 | M9: 32 | N9: 7 | O9: 25 | P9: 4 | Q9: 3 | R9: 1 | S9: 3 | T9: 22 | U9: 16 | V9: 11 | W9: 34 | X9: 31 | Y9: 10 | Z9: 11 | AA9: 31 | AB9: 23 | AM9: =SUM(C9:AL9) -> 416
A10: 7 | B10: Dainel Suarez | Y10: 14 | Z10: 21 | AA10: 20 | AB10: 38 | AM10: =SUM(C10:AL10) -> 93 | AN10: Hackman | AO10: Bell | AQ10: Kevin | AR10: Larson | AT10: Jason | AU10: Larson
A11: 8 | B11: K. Busch | C11: 29 | D11: 7 | E11: 25 | F11: 20 | G11: 9 | H11: 16 | I11: 13 | J11: 12 | K11: 2 | L11: 27 | M11: 22 | N11: 35 | O11: 0 | P11: 0 | Q11: 0 | R11: 0 | S11: 0 | T11: 0 | U11: 0 | V11: 0 | W11: 0 | X11: 0 | Y11: 0 | Z11: 0 | AA11: 0 | AB11: 0 | AM11: =SUM(C11:AL11) -> 217 | AO11: Buscher | AR11: Wallace | AU11: Buscher
A12: 9 | B12: C. Elliot | C12: 33 | D12: 38 | E12: 33 | F12: 14 | G12: 40 | H12: 26 | I12: 55 | J12: 15 | K12: 41 | L12: 35 | M12: 69 | N12: 13 | O12: 1 | P12: 37 | Q12: 22 | R12: 27 | S12: 25 | T12: 20 | U12: 30 | V12: 26 | W12: 24 | X12: 1 | Y12: 22 | Z12: 38 | AA12: 12 | AB12: 16 | AM12: =SUM(C12:AL12) -> 713
A13: 10 | B13: T. Dillon | Y13: 13 | Z13: 5 | AA13: 10 | AB13: 16 | AM13: =SUM(C13:AL13) -> 44 | AN13: Tony (1) | AO13: Briscoe | AQ13: Gehr (1) | AR13: Byron | AT13: Shenk | AU13: Hamlin
A14: 11 | B14: D. Hamlin | C14: 6 | D14: 24 | E14: 28 | F14: 47 | G14: 70 | H14: 26 | I14: 56 | J14: 41 | K14: 52 | L14: 22 | M14: 43 | N14: 21 | O14: 60 | P14: 62 | Q14: 58 | R14: 67 | S14: 23 | T14: 11 | U14: 45 | V14: 27 | W14: 51 | X14: 44 | Y14: 37 | Z14: 46 | AA14: 32 | AB14: 26 | AM14: =SUM(C14:AL14) -> 1025 | AO14: Hosevar | AR14: Gibbs | AU14: Logano
A15: 12 | B15: R. Blaney | C15: 27 | D15: 31 | E15: 33 | F15: 65 | G15: 23 | H15: 42 | I15: 41 | J15: 53 | K15: 13 | L15: 7 | M15: 27 | N15: 34 | O15: 41 | P15: 37 | Q15: 29 | R15: 27 | S15: 44 | T15: 32 | U15: 36 | V15: 75 | W15: 29 | X15: 11 | Y15: 47 | Z15: 40 | AA15: 70 | AB15: 14 | AM15: =SUM(C15:AL15) -> 928
A16: 15 | B16: T. Brown | AM16: =SUM(C16:AL16) -> 0 | AN16: Gass | AO16: Hamlin | AQ16: Devin (1) | AR16: Hamlin | AT16: Sasko | AU16: Bell
A17: 16 | B17: A. Allmedinger | Y17: 29 | Z17: 4 | AA17: 14 | AB17: 7 | AM17: =SUM(C17:AL17) -> 54 | AO17: Gibbs | AR17: Hosevar | AU17: K. Busch
A18: 17 | B18: C. Buscher | C18: 39 | D18: 22 | E18: 19 | F18: 30 | G18: 35 | H18: 42 | I18: 18 | J18: 24 | K18: 29 | L18: 50 | M18: 36 | N18: 30 | O18: 10 | P18: 8 | Q18: 31 | R18: 37 | S18: 39 | T18: 18 | U18: 23 | V18: 27 | W18: 17 | X18: 28 | Y18: 24 | Z18: 16 | AA18: 23 | AB18: 1 | AM18: =SUM(C18:AL18) -> 676
A19: 19 | B19: C. Briscoe | C19: 1 | D19: 43 | E19: 1 | F19: 1 | G19: 29 | H19: 32 | I19: 23 | J19: 45 | K19: 38 | L19: 8 | M19: 20 | N19: 35 | O19: 27 | P19: 39 | Q19: 27 | R19: 41 | S19: 20 | T19: 37 | U19: 70 | V19: 4 | W19: 45 | X19: 36 | Y19: 40 | Z19: 52 | AA19: 12 | AB19: 34 | AM19: =SUM(C19:AL19) -> 760 | AN19: Kilhefner (3) | AO19: Blaney | AQ19: Jack-n-Bob | AR19: Conner Z. | AT19: Kyle (1) | AU19: Byron
A20: 20 | B20: C. Bell | C20: 2 | D20: 16 | E20: 34 | F20: 54 | G20: 51 | H20: 18 | I20: 30 | J20: 19 | K20: 30 | L20: 29 | M20: 1 | N20: 20 | O20: 50 | P20: 38 | Q20: 11 | R20: 11 | S20: 1 | T20: 50 | U20: 40 | V20: 39 | W20: 23 | X20: 35 | Y20: 50 | Z20: 36 | AA20: 43 | AB20: 20 | AM20: =SUM(C20:AL20) -> 751 | AO20: Chastain | AR20: E. Jones | AU20: Gibbs
A21: 21 | B21: J. Berry | Y21: 33 | Z21: 40 | AA21: 49 | AB21: 28 | AM21: =SUM(C21:AL21) -> 150
A22: 22 | B22: J. Lagano | C22: 36 | D22: 22 | E22: 22 | F22: 23 | G22: 22 | H22: 4 | I22: 46 | J22: 33 | K22: 7 | L22: 9 | M22: 1 | N22: 10 | O22: 29 | P22: 23 | Q22: 32 | R22: 5 | S22: 23 | T22: 13 | U22: 25 | V22: 43 | W22: 73 | X22: 34 | Y22: 41 | Z22: 73 | AA22: 23 | AB22: 27 | AM22: =SUM(C22:AL22) -> 699 | AN22: Dani(1) | AO22: Larson | AQ22: Ray (2) | AR22: Blaney | AT22: Burrey (2) | AU22: Blaney
A23: 23 | B23: B. Wallace | C23: 37 | D23: 48 | E23: 31 | F23: 37 | G23: 41 | H23: 10 | I23: 1 | J23: 30 | K23: 39 | L23: 1 | M23: 28 | N23: 9 | O23: 15 | P23: 10 | Q23: 40 | R23: 16 | S23: 35 | T23: 15 | U23: 40 | V23: 9 | W23: 38 | X23: 9 | Y23: 25 | Z23: 22 | AA23: 43 | AB23: 21 | AM23: =SUM(C23:AL23) -> 650 | AO23: Bubba | AR23: Van Gisbergen | AU23: Hosevar
A24: 24 | B24: W. Byron | C24: 25 | D24: 25 | E24: 26 | F24: 32 | G24: 49 | H24: 34 | I24: 47 | J24: 7 | K24: 30 | L24: 2 | M24: 31 | N24: 1 | O24: 28 | P24: 15 | Q24: 25 | R24: 38 | S24: 6 | T24: 25 | U24: 53 | V24: 21 | W24: 26 | X24: 22 | Y24: 32 | Z24: 30 | AA24: 14 | AB24: 22 | AM24: =SUM(C24:AL24) -> 666
A25: 31 | B25: D. Hemric | AM25: =SUM(C25:AL25) -> 0 | AN25: 8 | AO25: A | AQ25: Rob | AR25: Elliott | AT25: 8 | AU25: A
A26: 33 | B26: A. Hill | Y26: 0 | Z26: 0 | AA26: 0 | AB26: 0 | AM26: =SUM(C26:AL26) -> 0 | AO26: B | AR26: Reddick | AU26: B
A27: 34 | B27: T. Gilliland | Y27: 15 | Z27: 7 | AA27: 16 | AB27: 24 | AM27: =SUM(C27:AL27) -> 62
A28: 35 | B28: R. Herbst | Y28: 16 | Z28: 13 | AA28: 3 | AB28: 0 | AM28: =SUM(C28:AL28) -> 32 | AN28: 9 | AO28: A | AQ28: 9 | AR28: A | AT28: 9 | AU28: A
A29: 38 | B29: Z. Smith | Y29: 24 | Z29: 1 | AA29: 24 | AB29: 13 | AM29: =SUM(C29:AL29) -> 62 | AO29: B | AR29: B | AU29: B
A30: 41 | B30: C. Custer | Y30: 9 | Z30: 8 | AA30: 15 | AB30: 27 | AM30: =SUM(C30:AL30) -> 59
A31: 42 | B31: J. Nemecheck | Y31: 18 | Z31: 15 | AA31: 6 | AB31: 24 | AM31: =SUM(C31:AL31) -> 63 | AN31: 10 | AO31: A | AQ31: 10 | AR31: A | AT31: 10 | AU31: A
A32: 43 | B32: E. Jones | C32: 16 | D32: 13 | E32: 3 | F32: 27 | G32: 17 | H32: 27 | I32: 16 | J32: 14 | K32: 14 | L32: 14 | M32: 35 | N32: 18 | O32: 30 | P32: 26 | Q32: 44 | R32: 41 | S32: 17 | T32: 17 | U32: 22 | V32: 35 | W32: 16 | X32: 12 | Y32: 2 | Z32: 10 | AA32: 4 | AB32: 8 | AM32: =SUM(C32:AL32) -> 498 | AO32: B | AR32: B | AU32: B
A33: 44 | B33: JJ Yeley | AM33: =SUM(C33:AL33) -> 0
A34: 45 | B34: T. Reddick | C34: 58 | D34: 67 | E34: 61 | F34: 39 | G34: 30 | H34: 70 | I34: 28 | J34: 33 | K34: 71 | L34: 27 | M34: 42 | N34: 41 | O34: 53 | P34: 37 | Q34: 12 | R34: 35 | S34: 12 | T34: 2 | U34: 2 | V34: 47 | W34: 7 | X34: 28 | Y34: 1 | Z34: 28 | AA34: 29 | AB34: 34 | AM34: =SUM(C34:AL34) -> 894
A35: 47 | B35: R. Stenhouse Jr. | Y35: 19 | Z35: 6 | AA35: 9 | AB35: 32 | AM35: =SUM(C35:AL35) -> 66
A36: 48 | B36: A. Bowman | C36: 3 | D36: 14 | E36: 5 | F36: 0 | G36: 0 | H36: 0 | I36: 0 | J36: 1 | K36: 19 | L36: 37 | M36: 35 | N36: 12 | O36: 20 | P36: 13 | Q36: 18 | R36: 10 | S36: 11 | T36: 32 | U36: 35 | V36: 15 | W36: 11 | X36: 18 | Y36: 3 | Z36: 27 | AA36: 22 | AB36: 29 | AM36: =SUM(C36:AL36) -> 390
A37: 50 | B37: B Myers | AM37: =SUM(C37:AL37) -> 0
A38: 51 | B38: C Ware | Y38: 5 | Z38: 3 | AA38: 8 | AB38: 2 | AM38: =SUM(C38:AL38) -> 18
A39: 54 | B39: T. Gibbs | C39: 14 | D39: 1 | E39: 48 | F39: 36 | G39: 39 | H39: 33 | I39: 49 | J39: 59 | K39: 38 | L39: 3 | M39: 8 | N39: 42 | O39: 53 | P39: 24 | Q39: 21 | R39: 36 | S39: 29 | T39: 54 | U39: 38 | V39: 38 | W39: 43 | X39: 43 | Y39: 69 | Z39: 22 | AA39: 38 | AB39: 12 | AM39: =SUM(C39:AL39) -> 890
A40: 60 | B40: R. Prece | Y40: 17 | Z40: 20 | AA40: 38 | AB40: 67 | AM40: =SUM(C40:AL40) -> 142
...

Sheet Red Fantasy Standings
A1: 2025 | C1: RED Fantasy Nascar League
A3: Owner | B3: Driver | C3: Race 01 | D3: Race 02 | E3: Race 03 | F3: Race 04 | G3: Race 05 | H3: Race 06 | I3: Race 07 | J3: Race 08 | K3: Race 09 | L3: Race 10 | M3: Race 11 | N3: Race 12 | O3: Race 13 | P3: Race 14 | Q3: Race 15 | R3: Race 16 | S3: Race 17 | T3: Race 18 | U3: Race 19 | V3: Race 20 | W3: Race 21 | X3: Race 22 | Y3: Race 23 | Z3: Race 24 | AA3: Race 25 | AB3: Race 26 | AC3: Race 27 | AD3: Race 28 | AE3: Race 29 | AF3: Race 30 | AG3: Race 31 | AH3: Race 32 | AI3: Race 33 | AJ3: Race 34 | AK3: Race 35 | AL3: Race 36 | AM3: Points | AN3: Ranking | AO3: AVG
A6: =Drivers!AN4 -> Dehaven | B6: =Drivers!AO4 -> Elliott | C6: =Drivers!C12 -> 33 | D6: =Drivers!D12 -> 38 | E6: =Drivers!E12 -> 33 | F6: =Drivers!F12 -> 14 | G6: =Drivers!G12 -> 40 | H6: =Drivers!H12 -> 26 | I6: =Drivers!I12 -> 55 | J6: =Drivers!J12 -> 15 | ... AL6: =Drivers!AL12 | AM6: =SUM(C8:AL8) -> 1607 | AN6: =RANK($AM$6:$AM$35,$AM$6:$AM$35,1>10) -> 2 | AO6: =AVERAGE(C8:AL8) -> 44.638889
B7: =Drivers!AO5 -> Reddick | C7: =Drivers!C34 -> 58 | D7: =Drivers!D34 -> 67 | E7: =Drivers!E34 -> 61 | F7: =Drivers!F34 -> 39 | G7: =Drivers!G34 -> 30 | H7: =Drivers!H34 -> 70 | I7: =Drivers!I34 -> 28 | J7: =Drivers!J34 -> 33 | ... AL7: =Drivers!AL34
C8: =SUM(C6+C7) -> 91 | D8: =SUM(D6+D7) -> 105 | E8: =SUM(E6+E7) -> 94 | F8: =SUM(F6+F7) -> 53 | G8: =SUM(G6+G7) -> 70 | H8: =SUM(H6+H7) -> 96 | I8: =SUM(I6+I7) -> 83 | J8: =SUM(J6+J7) -> 48 | ... AL8: =SUM(AL6+AL7) -> 0
A9: =Drivers!AN7 -> Gehman (1) | B9: =Drivers!AO7 -> Byron | C9: =Drivers!C24 -> 25 | D9: =Drivers!D24 -> 25 | E9: =Drivers!E24 -> 26 | F9: =Drivers!F24 -> 32 | G9: =Drivers!G24 -> 49 | H9: =Drivers!H24 -> 34 | I9: =Drivers!I24 -> 47 | J9: =Drivers!J24 -> 7 | ... AL9: =Drivers!AL24 | AM9: =SUM(C11:AL11) -> 1366 | AN9: =RANK($AM$6:$AM$35,$AM$6:$AM$35,1>10) -> 4 | AO9: =AVERAGE(C11:AL11) -> 37.944444
B10: =Drivers!AO8 -> Logano | C10: =Drivers!C4 -> 17 | D10: =Drivers!D4 -> 34 | E10: =Drivers!E4 -> 13 | F10: =Drivers!F4 -> 10 | G10: =Drivers!G4 -> 20 | H10: =Drivers!H4 -> 21 | I10: =Drivers!I4 -> 21 | J10: =Drivers!J4 -> 17 | ... N10: =Drivers!N4 -> 20 | O10: =Drivers!O22 -> 29 | P10: =Drivers!P22 -> 23 | Q10: =Drivers!Q22 -> 32 | R10: =Drivers!R22 -> 5 | S10: =Drivers!S22 -> 23 | T10: =Drivers!T22 -> 13 | U10: =Drivers!U22 -> 25 | V10: =Drivers!V22 -> 43 | ... AL10: =Drivers!AL22
C11: =SUM(C9+C10) -> 42 | D11: =SUM(D9+D10) -> 59 | E11: =SUM(E9+E10) -> 39 | F11: =SUM(F9+F10) -> 42 | G11: =SUM(G9+G10) -> 69 | H11: =SUM(H9+H10) -> 55 | I11: =SUM(I9+I10) -> 68 | J11: =SUM(J9+J10) -> 24 | ... AL11: =SUM(AL9+AL10) -> 0
A12: =Drivers!AN10 -> Hackman | B12: =Drivers!AO10 -> Bell | C12: =Drivers!C20 -> 2 | D12: =Drivers!D20 -> 16 | E12: =Drivers!E20 -> 34 | F12: =Drivers!F20 -> 54 | G12: =Drivers!G20 -> 51 | H12: =Drivers!H20 -> 18 | I12: =Drivers!I20 -> 30 | J12: =Drivers!J20 -> 19 | ... AL12: =Drivers!AL20 | AM12: =SUM(C14:AL14) -> 1427 | AN12: =RANK($AM$6:$AM$35,$AM$6:$AM$35,1>10) -> 3 | AO12: =AVERAGE(C14:AL14) -> 39.638889
B13: =Drivers!AO11 -> Buscher | C13: =Drivers!C18 -> 39 | D13: =Drivers!D18 -> 22 | E13: =Drivers!E18 -> 19 | F13: =Drivers!F18 -> 30 | G13: =Drivers!G18 -> 35 | H13: =Drivers!H18 -> 42 | I13: =Drivers!I18 -> 18 | J13: =Drivers!J18 -> 24 | ... AL13: =Drivers!AL18
C14: =SUM(C12:C13) -> 41 | D14: =SUM(D12+D13) -> 38 | E14: =SUM(E12+E13) -> 53 | F14: =SUM(F12+F13) -> 84 | G14: =SUM(G12+G13) -> 86 | H14: =SUM(H12+H13) -> 60 | I14: =SUM(I12+I13) -> 48 | J14: =SUM(J12+J13) -> 43 | K14: =SUM(K12+K13) -> 59 | ... AL14: =SUM(AL12+AL13) -> 0
A15: =Drivers!AN13 -> Tony (1) | B15: =Drivers!AO13 -> Briscoe | C15: =Drivers!C19 -> 1 | D15: =Drivers!D19 -> 43 | E15: =Drivers!E19 -> 1 | F15: =Drivers!F19 -> 1 | G15: =Drivers!G19 -> 29 | H15: =Drivers!H19 -> 32 | I15: =Drivers!I19 -> 23 | J15: =Drivers!J19 -> 45 | ... AL15: =Drivers!AL19 | AM15: =SUM(C17:AL17) -> 1325 | AN15: =RANK($AM$6:$AM$35,$AM$6:$AM$35,1>10) -> 6 | AO15: =AVERAGE(C17:AL17) -> 36.805556
B16: =Drivers!AO14 -> Hosevar | C16: =Drivers!C22 -> 36 | D16: =Drivers!D22 -> 22 | E16: =Drivers!E22 -> 22 | F16: =Drivers!F22 -> 23 | G16: =Drivers!G22 -> 22 | H16: =Drivers!H22 -> 4 | I16: =Drivers!I22 -> 46 | J16: =Drivers!J22 -> 33 | ... M16: =Drivers!M22 -> 1 | N16: =Drivers!N42 -> 9 | O16: =Drivers!O42 -> 14 | P16: =Drivers!P42 -> 27 | Q16: =Drivers!Q42 -> 45 | R16: =Drivers!R42 -> 21 | S16: =Drivers!S42 -> 27 | T16: =Drivers!T42 -> 33 | U16: =Drivers!U42 -> 15 | ... AL16: =Drivers!AL42
C17: =SUM(C15+C16) -> 37 | D17: =SUM(D15+D16) -> 65 | E17: =SUM(E15+E16) -> 23 | F17: =SUM(F15+F16) -> 24 | G17: =SUM(G15+G16) -> 51 | H17: =SUM(H15+H16) -> 36 | I17: =SUM(I15+I16) -> 69 | J17: =SUM(J15+J16) -> 78 | ... AL17: =SUM(AL15+AL16) -> 0
A18: =Drivers!AN16 -> Gass | B18: =Drivers!AO16 -> Hamlin | C18: =Drivers!C14 -> 6 | D18: =Drivers!D14 -> 24 | E18: =Drivers!E14 -> 28 | F18: =Drivers!F14 -> 47 | G18: =Drivers!G14 -> 70 | H18: =Drivers!H14 -> 26 | I18: =Drivers!I14 -> 56 | J18: =Drivers!J14 -> 41 | ... AL18: =Drivers!AL14 | AM18: =SUM(C20:AL20) -> 1915 | AN18: =RANK($AM$6:$AM$35,$AM$6:$AM$35,1>10) -> 1 | AO18: =AVERAGE(C20:AL20) -> 53.194444
B19: =Drivers!AO17 -> Gibbs | C19: =Drivers!C39 -> 14 | D19: =Drivers!D39 -> 1 | E19: =Drivers!E39 -> 48 | F19: =Drivers!F39 -> 36 | G19: =Drivers!G39 -> 39 | H19: =Drivers!H39 -> 33 | I19: =Drivers!I39 -> 49 | J19: =Drivers!J39 -> 59 | ... AL19: =Drivers!AL39
C20: =SUM(C18+C19) -> 20 | D20: =SUM(D18+D19) -> 25 | E20: =SUM(E18+E19) -> 76 | F20: =SUM(F18+F19) -> 83 | G20: =SUM(G18+G19) -> 109 | H20: =SUM(H18+H19) -> 59 | I20: =SUM(I18+I19) -> 105 | J20: =SUM(J18+J19) -> 100 | ... AL20: =SUM(AL18+AL19) -> 0
A21: =Drivers!AN19 -> Kilhefner (3) | B21: =Drivers!AO19 -> Blaney | C21: =Drivers!C15 -> 27 | D21: =Drivers!D15 -> 31 | E21: =Drivers!E15 -> 33 | F21: =Drivers!F15 -> 65 | G21: =Drivers!G15 -> 23 | H21: =Drivers!H15 -> 42 | I21: =Drivers!I15 -> 41 | J21: =Drivers!J15 -> 53 | ... AL21: =Drivers!AL15 | AM21: =SUM(C23:AL23) -> 1353 | AN21: =RANK($AM$6:$AM$35,$AM$6:$AM$35,1>10) -> 5 | AO21: =AVERAGE(C23:AL23) -> 37.583333
B22: =Drivers!AO20 -> Chastain | C22: =Drivers!C36 -> 3 | D22: =Drivers!D36 -> 14 | E22: =Drivers!E36 -> 5 | F22: =Drivers!F46 -> 26 | G22: =Drivers!G46 -> 1 | H22: =Drivers!H46 -> 23 | I22: =Drivers!I46 -> 34 | J22: =Drivers!J46 -> 3 | K22: =Drivers!K9 -> 35 | L22: =Drivers!L9 -> 15 | M22: =Drivers!M9 -> 32 | N22: =Drivers!N9 -> 7 | O22: =Drivers!O9 -> 25 | P22: =Drivers!P9 -> 4 | Q22: =Drivers!Q9 -> 3 | R22: =Drivers!R9 -> 1 | S22: =Drivers!S9 -> 3 | T22: =Drivers!T4 -> 29 | U22: =Drivers!U4 -> 19 | V22: =Drivers!V4 -> 26 | W22: =Drivers!W4 -> 11 | X22: =Drivers!X4 -> 24 | Y22: =Drivers!Y4 -> 43 | Z22: =Drivers!Z4 -> 25 | AA22: =Drivers!AA4 -> 1 | ... AL22: =Drivers!AL4
C23: =SUM(C21+C22) -> 30 | D23: =SUM(D21+D22) -> 45 | E23: =SUM(E21+E22) -> 38 | F23: =SUM(F21+F22) -> 91 | G23: =SUM(G21+G22) -> 24 | H23: =SUM(H21+H22) -> 65 | I23: =SUM(I21+I22) -> 75 | J23: =SUM(J21+J22) -> 56 | ... AL23: =SUM(AL21+AL22) -> 0
A24: =Drivers!AN22 -> Dani(1) | B24: =Drivers!AO22 -> Larson | C24: =Drivers!C8 -> 21 | D24: =Drivers!D8 -> 13 | E24: =Drivers!E8 -> 31 | F24: =Drivers!F8 -> 36 | G24: =Drivers!G8 -> 48 | H24: =Drivers!H8 -> 19 | I24: =Drivers!I8 -> 30 | J24: =Drivers!J8 -> 54 | ... AL24: =Drivers!AL8 | AM24: =SUM(C26:AL26) -> 1271 | AN24: =RANK($AM$6:$AM$35,$AM$6:$AM$35,1>10) -> 7 | AO24: =AVERAGE(C26:AL26) -> 35.305556
B25: =Drivers!AO23 -> Bubba | C25: =Drivers!C5 -> 12 | D25: =Drivers!D5 -> 21 | E25: =Drivers!E5 -> 5 | F25: =Drivers!F23 -> 37 | G25: =Drivers!G23 -> 41 | H25: =Drivers!H23 -> 10 | I25: =Drivers!I23 -> 1 | J25: =Drivers!J23 -> 30 | K25: =Drivers!K23 -> 39 | L25: =Drivers!L23 -> 1 | M25: =Drivers!M23 -> 28 | ... AL25: =Drivers!AL23
C26: =SUM(C24+C25) -> 33 | D26: =SUM(D24+D25) -> 34 | E26: =SUM(E24+E25) -> 36 | F26: =SUM(F24+F25) -> 73 | G26: =SUM(G24+G25) -> 89 | H26: =SUM(H24+H25) -> 29 | I26: =SUM(I24+I25) -> 31 | J26: =SUM(J24+J25) -> 84 | ... AL26: =SUM(AL24+AL25) -> 0
A27: =Drivers!AN25 -> 8 | B27: =Drivers!AO25 -> A | AM27: =SUM(C29:AL29) -> 0 | AN27: =RANK($AM$6:$AM$35,$AM$6:$AM$35,1>10) -> 8 | AO27: =AVERAGE(C29:AL29) -> 0
B28: =Drivers!AO26 -> B
C29: =SUM(C27+C28) -> 0 | D29: =SUM(D27+D28) -> 0 | E29: =SUM(E27+E28) -> 0 | F29: =SUM(F27+F28) -> 0 | G29: =SUM(G27+G28) -> 0 | H29: =SUM(H27+H28) -> 0 | I29: =SUM(I27+I28) -> 0 | J29: =SUM(J27+J28) -> 0 | ... AL29: =SUM(AL27+AL28) -> 0
A30: =Drivers!AN28 -> 9 | B30: =Drivers!AO28 -> A | AM30: =SUM(C32:AL32) -> 0 | AN30: =RANK($AM$6:$AM$35,$AM$6:$AM$35,1>10) -> 8 | AO30: =AVERAGE(C32:AL32) -> 0
B31: =Drivers!AO29 -> B
C32: =SUM(C30+C31) -> 0 | D32: =SUM(D30+D31) -> 0 | E32: =SUM(E30+E31) -> 0 | F32: =SUM(F30+F31) -> 0 | G32: =SUM(G30+G31) -> 0 | H32: =SUM(H30+H31) -> 0 | I32: =SUM(I30+I31) -> 0 | J32: =SUM(J30+J31) -> 0 | ... AL32: =SUM(AL30+AL31) -> 0
A33: =Drivers!AN31 -> 10 | B33: =Drivers!AO31 -> A | AM33: =SUM(C35:AL35) -> 0 | AN33: =RANK($AM$6:$AM$35,$AM$6:$AM$35,1>10) -> 8
B34: =Drivers!AO32 -> B
C35: =SUM(C33+C34) -> 0 | D35: =SUM(D33+D34) -> 0 | E35: =SUM(E33+E34) -> 0 | F35: =SUM(F33+F34) -> 0 | G35: =SUM(G33+G34) -> 0 | H35: =SUM(H33+H34) -> 0 | I35: =SUM(I33+I34) -> 0 | J35: =SUM(J33+J34) -> 0 | ... AL35: =SUM(AL33+AL34) -> 0

Sheet Leader Board Red

Sheet White Fantasy Standings
A1: 2025 | C1: White Fantasy Nascar League
A3: Owner | B3: Driver | C3: Race 01 | D3: Race 02 | E3: Race 03 | F3: Race 04 | G3: Race 05 | H3: Race 06 | I3: Race 07 | J3: Race 08 | K3: Race 09 | L3: Race 10 | M3: Race 11 | N3: Race 12 | O3: Race 13 | P3: Race 14 | Q3: Race 15 | R3: Race 16 | S3: Race 17 | T3: Race 18 | U3: Race 19 | V3: Race 20 | W3: Race 21 | X3: Race 22 | Y3: Race 23 | Z3: Race 24 | AA3: Race 25 | AB3: Race 26 | AC3: Race 27 | AD3: Race 28 | AE3: Race 29 | AF3: Race 30 | AG3: Race 31 | AH3: Race 32 | AI3: Race 33 | AJ3: Race 34 | AK3: Race 35 | AL3: Race 36 | AM3: Points | AN3: Ranking | AO3: AVG
A6: =Drivers!AQ4 -> Dustin | B6: =Drivers!AR4 -> Briscoe | C6: =Drivers!C19 -> 1 | D6: =Drivers!D19 -> 43 | E6: =Drivers!E19 -> 1 | F6: =Drivers!F19 -> 1 | G6: =Drivers!G19 -> 29 | H6: =Drivers!H19 -> 32 | I6: =Drivers!I19 -> 23 | J6: =Drivers!J19 -> 45 | ... AL6: =Drivers!AL19 | AM6: =SUM(C8:AL8) -> 1459 | AN6: =RANK($AM$6:$AM$35,$AM$6:$AM$35,1>10) -> 5 | AO6: =AVERAGE(C8:AL8) -> 40.527778
B7: =Drivers!AR5 -> Logano | C7: =Drivers!C22 -> 36 | D7: =Drivers!D22 -> 22 | E7: =Drivers!E22 -> 22 | F7: =Drivers!F22 -> 23 | G7: =Drivers!G22 -> 22 | H7: =Drivers!H22 -> 4 | I7: =Drivers!I22 -> 46 | J7: =Drivers!J22 -> 33 | ... AL7: =Drivers!AL22
C8: =SUM(C6+C7) -> 37 | D8: =SUM(D6+D7) -> 65 | E8: =SUM(E6+E7) -> 23 | F8: =SUM(F6+F7) -> 24 | G8: =SUM(G6+G7) -> 51 | H8: =SUM(H6+H7) -> 36 | I8: =SUM(I6+I7) -> 69 | J8: =SUM(J6+J7) -> 78 | ... AL8: =SUM(AL6+AL7) -> 0
A9: =Drivers!AQ7 -> Derrick | B9: =Drivers!AR7 -> Bell | C9: =Drivers!C20 -> 2 | D9: =Drivers!D20 -> 16 | E9: =Drivers!E20 -> 34 | F9: =Drivers!F20 -> 54 | G9: =Drivers!G20 -> 51 | H9: =Drivers!H20 -> 18 | I9: =Drivers!I20 -> 30 | J9: =Drivers!J20 -> 19 | ... AL9: =Drivers!AL20 | AM9: =SUM(C11:AL11) -> 1427 | AN9: =RANK($AM$6:$AM$35,$AM$6:$AM$35,1>10) -> 6 | AO9: =AVERAGE(C11:AL11) -> 39.638889
B10: =Drivers!AR8 -> Buscher | C10: =Drivers!C18 -> 39 | D10: =Drivers!D18 -> 22 | E10: =Drivers!E18 -> 19 | F10: =Drivers!F18 -> 30 | G10: =Drivers!G18 -> 35 | H10: =Drivers!H18 -> 42 | I10: =Drivers!I18 -> 18 | J10: =Drivers!J18 -> 24 | ... AL10: =Drivers!AL18
C11: =SUM(C9+C10) -> 41 | D11: =SUM(D9+D10) -> 38 | E11: =SUM(E9+E10) -> 53 | F11: =SUM(F9+F10) -> 84 | G11: =SUM(G9+G10) -> 86 | H11: =SUM(H9+H10) -> 60 | I11: =SUM(I9+I10) -> 48 | J11: =SUM(J9+J10) -> 43 | ... AL11: =SUM(AL9+AL10) -> 0
A12: =Drivers!AQ10 -> Kevin | B12: =Drivers!AR10 -> Larson | C12: =Drivers!C8 -> 21 | D12: =Drivers!D8 -> 13 | E12: =Drivers!E8 -> 31 | F12: =Drivers!F8 -> 36 | G12: =Drivers!G8 -> 48 | H12: =Drivers!H8 -> 19 | I12: =Drivers!I8 -> 30 | J12: =Drivers!J8 -> 54 | ... AL12: =Drivers!AL8 | AM12: =SUM(C14:AL14) -> 1349 | AN12: =RANK($AM$6:$AM$35,$AM$6:$AM$35,1>10) -> 7 | AO12: =AVERAGE(C14:AL14) -> 37.472222
B13: =Drivers!AR11 -> Wallace | C13: =Drivers!C23 -> 37 | D13: =Drivers!D23 -> 48 | E13: =Drivers!E23 -> 31 | F13: =Drivers!F23 -> 37 | G13: =Drivers!G23 -> 41 | H13: =Drivers!H23 -> 10 | I13: =Drivers!I23 -> 1 | J13: =Drivers!J23 -> 30 | ... AL13: =Drivers!AL23
C14: =SUM(C12+C13) -> 58 | D14: =SUM(D12+D13) -> 61 | E14: =SUM(E12+E13) -> 62 | F14: =SUM(F12+F13) -> 73 | G14: =SUM(G12+G13) -> 89 | H14: =SUM(H12+H13) -> 29 | I14: =SUM(I12+I13) -> 31 | J14: =SUM(J12+J13) -> 84 | ... AL14: =SUM(AL12+AL13) -> 0
A15: =Drivers!AQ13 -> Gehr (1) | B15: =Drivers!AR13 -> Byron | C15: =Drivers!C24 -> 25 | D15: =Drivers!D24 -> 25 | E15: =Drivers!E24 -> 26 | F15: =Drivers!F24 -> 32 | G15: =Drivers!G24 -> 49 | H15: =Drivers!H24 -> 34 | I15: =Drivers!I24 -> 47 | J15: =Drivers!J24 -> 7 | ... AL15: =Drivers!AL24 | AM15: =SUM(C17:AL17) -> 1538 | AN15: =RANK($AM$6:$AM$35,$AM$6:$AM$35,1>10) -> 3 | AO15: =AVERAGE(C17:AL17) -> 42.722222
B16: =Drivers!AR14 -> Gibbs | C16: =Drivers!C11 -> 29 | D16: =Drivers!D11 -> 7 | E16: =Drivers!E11 -> 25 | F16: =Drivers!F11 -> 20 | G16: =Drivers!G39 -> 39 | H16: =Drivers!H39 -> 33 | I16: =Drivers!I39 -> 49 | J16: =Drivers!J39 -> 59 | K16: =Drivers!K39 -> 38 | L16: =Drivers!L39 -> 3 | M16: =Drivers!M39 -> 8 | N16: =Drivers!N39 -> 42 | ... AL16: =Drivers!AL39
C17: =SUM(C15+C16) -> 54 | D17: =SUM(D15+D16) -> 32 | E17: =SUM(E15+E16) -> 51 | F17: =SUM(F15+F16) -> 52 | G17: =SUM(G15+G16) -> 88 | H17: =SUM(H15+H16) -> 67 | I17: =SUM(I15+I16) -> 96 | J17: =SUM(J15+J16) -> 66 | ... AL17: =SUM(AL15+AL16) -> 0
A18: =Drivers!AQ16 -> Devin (1) | B18: =Drivers!AR16 -> Hamlin | C18: =Drivers!C14 -> 6 | D18: =Drivers!D14 -> 24 | E18: =Drivers!E14 -> 28 | F18: =Drivers!F14 -> 47 | G18: =Drivers!G14 -> 70 | H18: =Drivers!H14 -> 26 | I18: =Drivers!I14 -> 56 | J18: =Drivers!J14 -> 41 | ... AL18: =Drivers!AL14 | AM18: =SUM(C20:AL20) -> 1638 | AN18: =RANK($AM$6:$AM$35,$AM$6:$AM$35,1>10) -> 1 | AO18: =AVERAGE(C20:AL20) -> 45.5
B19: =Drivers!AR17 -> Hosevar | C19: =Drivers!C36 -> 3 | D19: =Drivers!D36 -> 14 | E19: =Drivers!E36 -> 5 | F19: =Drivers!F42 -> 21 | G19: =Drivers!G42 -> 15 | H19: =Drivers!H42 -> 33 | I19: =Drivers!I42 -> 20 | J19: =Drivers!J42 -> 38 | K19: =Drivers!K42 -> 28 | L19: =Drivers!L42 -> 55 | M19: =Drivers!M42 -> 41 | ... AL19: =Drivers!AL42
C20: =SUM(C18+C19) -> 9 | D20: =SUM(D18+D19) -> 38 | E20: =SUM(E18+E19) -> 33 | F20: =SUM(F18+F19) -> 68 | G20: =SUM(G18+G19) -> 85 | H20: =SUM(H18+H19) -> 59 | I20: =SUM(I18+I19) -> 76 | J20: =SUM(J18+J19) -> 79 | ... AL20: =SUM(AL18+AL19) -> 0
A21: =Drivers!AQ19 -> Jack-n-Bob | B21: =Drivers!AR19 -> Conner Z. | C21: =Drivers!C45 -> 4 | D21: =Drivers!D45 -> 9 | E21: =Drivers!E45 -> 23 | F21: =Drivers!F45 -> 8 | G21: =Drivers!G45 -> 5 | H21: =Drivers!H45 -> 19 | I21: =Drivers!I45 -> 11 | J21: =Drivers!J45 -> 4 | ... AL21: =Drivers!AL45 | AM21: =SUM(C23:AL23) -> 768 | AN21: =RANK($AM$6:$AM$35,$AM$6:$AM$35,1>10) -> 8 | AO21: =AVERAGE(C23:AL23) -> 21.333333
B22: =Drivers!AR20 -> E. Jones | C22: =Drivers!C32 -> 16 | D22: =Drivers!D32 -> 13 | E22: =Drivers!E32 -> 3 | F22: =Drivers!F32 -> 27 | G22: =Drivers!G32 -> 17 | H22: =Drivers!H32 -> 27 | I22: =Drivers!I32 -> 16 | J22: =Drivers!J32 -> 14 | ... AL22: =Drivers!AL32
C23: =SUM(C21+C22) -> 20 | D23: =SUM(D21+D22) -> 22 | E23: =SUM(E21+E22) -> 26 | F23: =SUM(F21+F22) -> 35 | G23: =SUM(G21+G22) -> 22 | H23: =SUM(H21+H22) -> 46 | I23: =SUM(I21+I22) -> 27 | J23: =SUM(J21+J22) -> 18 | ... AL23: =SUM(AL21+AL22) -> 0
A24: =Drivers!AQ22 -> Ray (2) | B24: =Drivers!AR22 -> Blaney | C24: =Drivers!C15 -> 27 | D24: =Drivers!D15 -> 31 | E24: =Drivers!E15 -> 33 | F24: =Drivers!F15 -> 65 | G24: =Drivers!G15 -> 23 | H24: =Drivers!H15 -> 42 | I24: =Drivers!I15 -> 41 | J24: =Drivers!J15 -> 53 | ... AL24: =Drivers!AL15 | AM24: =SUM(C26:AL26) -> 1490 | AN24: =RANK($AM$6:$AM$35,$AM$6:$AM$35,1>10) -> 4 | AO24: =AVERAGE(C26:AL26) -> 41.388889
B25: =Drivers!AR23 -> Van Gisbergen | C25: =Drivers!C4 -> 17 | D25: =Drivers!D4 -> 34 | E25: =Drivers!E4 -> 13 | F25: =Drivers!F4 -> 10 | G25: =Drivers!G4 -> 20 | H25: =Drivers!H9 -> 55 | I25: =Drivers!I9 -> 24 | J25: =Drivers!J9 -> 23 | K25: =Drivers!K9 -> 35 | L25: =Drivers!L9 -> 15 | M25: =Drivers!M9 -> 32 | N25: =Drivers!N9 -> 7 | O25: =Drivers!O9 -> 25 | ... R25: =Drivers!R9 -> 1 | S25: =Drivers!S46 -> 1 | T25: =Drivers!T46 -> 63 | U25: =Drivers!U46 -> 12 | V25: =Drivers!V46 -> 32 | W25: =Drivers!W46 -> 47 | X25: =Drivers!X46 -> 21 | Y25: =Drivers!Y46 -> 7 | Z25: =Drivers!Z46 -> 23 | ... AL25: =Drivers!AL46
C26: =SUM(C24+C25) -> 44 | D26: =SUM(D24+D25) -> 65 | E26: =SUM(E24+E25) -> 46 | F26: =SUM(F24+F25) -> 75 | G26: =SUM(G24+G25) -> 43 | H26: =SUM(H24+H25) -> 97 | I26: =SUM(I24+I25) -> 65 | J26: =SUM(J24+J25) -> 76 | ... AL26: =SUM(AL24+AL25) -> 0
A27: =Drivers!AQ25 -> Rob | B27: =Drivers!AR25 -> Elliott | C27: =Drivers!C12 -> 33 | D27: =Drivers!D12 -> 38 | E27: =Drivers!E12 -> 33 | F27: =Drivers!F12 -> 14 | G27: =Drivers!G12 -> 40 | H27: =Drivers!H12 -> 26 | I27: =Drivers!I12 -> 55 | J27: =Drivers!J12 -> 15 | ... AL27: =Drivers!AL12 | AM27: =SUM(C29:AL29) -> 1607 | AN27: =RANK($AM$6:$AM$35,$AM$6:$AM$35,1>10) -> 2 | AO27: =AVERAGE(C29:AL29) -> 44.638889
B28: =Drivers!AR26 -> Reddick | C28: =Drivers!C34 -> 58 | D28: =Drivers!D34 -> 67 | E28: =Drivers!E34 -> 61 | F28: =Drivers!F34 -> 39 | G28: =Drivers!G34 -> 30 | H28: =Drivers!H34 -> 70 | I28: =Drivers!I34 -> 28 | J28: =Drivers!J34 -> 33 | ... AL28: =Drivers!AL34
C29: =SUM(C27+C28) -> 91 | D29: =SUM(D27+D28) -> 105 | E29: =SUM(E27+E28) -> 94 | F29: =SUM(F27+F28) -> 53 | G29: =SUM(G27+G28) -> 70 | H29: =SUM(H27+H28) -> 96 | I29: =SUM(I27+I28) -> 83 | J29: =SUM(J27+J28) -> 48 | ... AL29: =SUM(AL27+AL28) -> 0
A30: =Drivers!AQ28 -> 9 | B30: =Drivers!AR28 -> A | AM30: =SUM(C32:AL32) -> 0 | AN30: =RANK($AM$6:$AM$35,$AM$6:$AM$35,1>10) -> 9 | AO30: =AVERAGE(C32:AL32) -> 0
B31: =Drivers!AR29 -> B
C32: =SUM(C30+C31) -> 0 | D32: =SUM(D30+D31) -> 0 | E32: =SUM(E30+E31) -> 0 | F32: =SUM(F30+F31) -> 0 | G32: =SUM(G30+G31) -> 0 | H32: =SUM(H30+H31) -> 0 | I32: =SUM(I30+I31) -> 0 | J32: =SUM(J30+J31) -> 0 | ... AL32: =SUM(AL30+AL31) -> 0
A33: =Drivers!AQ31 -> 10 | B33: =Drivers!AR31 -> A | AM33: =SUM(C35:AL35) -> 0 | AN33: =RANK($AM$6:$AM$35,$AM$6:$AM$35,1>10) -> 9
B34: =Drivers!AR32 -> B
C35: =SUM(C33+C34) -> 0 | D35: =SUM(D33+D34) -> 0 | E35: =SUM(E33+E34) -> 0 | F35: =SUM(F33+F34) -> 0 | G35: =SUM(G33+G34) -> 0 | H35: =SUM(H33+H34) -> 0 | I35: =SUM(I33+I34) -> 0 | J35: =SUM(J33+J34) -> 0 | ... AL35: =SUM(AL33+AL34) -> 0

Sheet Leader Board White

Sheet Blue Fantasy Standings
A1: 2025 | C1: Blue Fantasy Nascar League
A3: Owner | B3: Driver | C3: Race 01 | D3: Race 02 | E3: Race 03 | F3: Race 04 | G3: Race 05 | H3: Race 06 | I3: Race 07 | J3: Race 08 | K3: Race 09 | L3: Race 10 | M3: Race 11 | N3: Race 12 | O3: Race 13 | P3: Race 14 | Q3: Race 15 | R3: Race 16 | S3: Race 17 | T3: Race 18 | U3: Race 19 | V3: Race 20 | W3: Race 21 | X3: Race 22 | Y3: Race 23 | Z3: Race 24 | AA3: Race 25 | AB3: Race 26 | AC3: Race 27 | AD3: Race 28 | AE3: Race 29 | AF3: Race 30 | AG3: Race 31 | AH3: Race 32 | AI3: Race 33 | AJ3: Race 34 | AK3: Race 35 | AL3: Race 36 | AM3: Points | AN3: Ranking | AO3: AVG
A6: =Drivers!AT4 -> Carole | B6: =Drivers!AU4 -> Elliott | C6: =Drivers!C12 -> 33 | D6: =Drivers!D12 -> 38 | E6: =Drivers!E12 -> 33 | F6: =Drivers!F12 -> 14 | G6: =Drivers!G12 -> 40 | H6: =Drivers!H12 -> 26 | I6: =Drivers!I12 -> 55 | J6: =Drivers!J12 -> 15 | ... AL6: =Drivers!AL12 | AM6: =SUM(C8:AL8) -> 1607 | AN6: =RANK($AM$6:$AM$35,$AM$6:$AM$35,1>10) -> 2 | AO6: =AVERAGE(C8:AL8) -> 44.638889
B7: =Drivers!AU5 -> Reddick | C7: =Drivers!C34 -> 58 | D7: =Drivers!D34 -> 67 | E7: =Drivers!E34 -> 61 | F7: =Drivers!F34 -> 39 | G7: =Drivers!G34 -> 30 | H7: =Drivers!H34 -> 70 | I7: =Drivers!I34 -> 28 | J7: =Drivers!J34 -> 33 | ... AL7: =Drivers!AL34
C8: =SUM(C6+C7) -> 91 | D8: =SUM(D6+D7) -> 105 | E8: =SUM(E6+E7) -> 94 | F8: =SUM(F6+F7) -> 53 | G8: =SUM(G6+G7) -> 70 | H8: =SUM(H6+H7) -> 96 | I8: =SUM(I6+I7) -> 83 | J8: =SUM(J6+J7) -> 48 | ... AL8: =SUM(AL6+AL7) -> 0
A9: =Drivers!AT7 -> Butch | B9: =Drivers!AU7 -> Briscoe | C9: =Drivers!C19 -> 1 | D9: =Drivers!D19 -> 43 | E9: =Drivers!E19 -> 1 | F9: =Drivers!F19 -> 1 | G9: =Drivers!G19 -> 29 | H9: =Drivers!H19 -> 32 | I9: =Drivers!I19 -> 23 | J9: =Drivers!J19 -> 45 | ... AL9: =Drivers!AL19 | AM9: =SUM(C11:AL11) -> 1359 | AN9: =RANK($AM$6:$AM$35,$AM$6:$AM$35,1>10) -> 6 | AO9: =AVERAGE(C11:AL11) -> 37.75
B10: =Drivers!AU8 -> Van Gisbergen | C10: =Drivers!C46 -> 7 | D10: =Drivers!D46 -> 32 | E10: =Drivers!E46 -> 45 | F10: =Drivers!F46 -> 26 | G10: =Drivers!G46 -> 1 | H10: =Drivers!H46 -> 23 | I10: =Drivers!I46 -> 34 | J10: =Drivers!J46 -> 3 | ... AL10: =Drivers!AL46
C11: =SUM(C9+C10) -> 8 | D11: =SUM(D9+D10) -> 75 | E11: =SUM(E9+E10) -> 46 | F11: =SUM(F9+F10) -> 27 | G11: =SUM(G9+G10) -> 30 | H11: =SUM(H9+H10) -> 55 | I11: =SUM(I9+I10) -> 57 | J11: =SUM(J9+J10) -> 48 | ... AL11: =SUM(AL9+AL10) -> 0
A12: =Drivers!AT10 -> Jason | B12: =Drivers!AU10 -> Larson | C12: =Drivers!C8 -> 21 | D12: =Drivers!D8 -> 13 | E12: =Drivers!E8 -> 31 | F12: =Drivers!F8 -> 36 | G12: =Drivers!G8 -> 48 | H12: =Drivers!H8 -> 19 | I12: =Drivers!I8 -> 30 | J12: =Drivers!J8 -> 54 | ... AL12: =Drivers!AL8 | AM12: =SUM(C14:AL14) -> 1375 | AN12: =RANK($AM$6:$AM$35,$AM$6:$AM$35,1>10) -> 5 | AO12: =AVERAGE(C14:AL14) -> 38.194444
B13: =Drivers!AU11 -> Buscher | C13: =Drivers!C18 -> 39 | D13: =Drivers!D18 -> 22 | E13: =Drivers!E18 -> 19 | F13: =Drivers!F18 -> 30 | G13: =Drivers!G18 -> 35 | H13: =Drivers!H18 -> 42 | I13: =Drivers!I18 -> 18 | J13: =Drivers!J18 -> 24 | ... AL13: =Drivers!AL18
C14: =SUM(C12+C13) -> 60 | D14: =SUM(D12+D13) -> 35 | E14: =SUM(E12+E13) -> 50 | F14: =SUM(F12+F13) -> 66 | G14: =SUM(G12+G13) -> 83 | H14: =SUM(H12+H13) -> 61 | I14: =SUM(I12+I13) -> 48 | J14: =SUM(J12+J13) -> 78 | ... AL14: =SUM(AL12+AL13) -> 0
A15: =Drivers!AT13 -> Shenk | B15: =Drivers!AU13 -> Hamlin | C15: =Drivers!C14 -> 6 | D15: =Drivers!D14 -> 24 | E15: =Drivers!E14 -> 28 | F15: =Drivers!F14 -> 47 | G15: =Drivers!G14 -> 70 | H15: =Drivers!H14 -> 26 | I15: =Drivers!I14 -> 56 | J15: =Drivers!J14 -> 41 | ... AL15: =Drivers!AL14 | AM15: =SUM(C17:AL17) -> 1724 | AN15: =RANK($AM$6:$AM$35,$AM$6:$AM$35,1>10) -> 1 | AO15: =AVERAGE(C17:AL17) -> 47.888889
B16: =Drivers!AU14 -> Logano | C16: =Drivers!C22 -> 36 | D16: =Drivers!D22 -> 22 | E16: =Drivers!E22 -> 22 | F16: =Drivers!F22 -> 23 | G16: =Drivers!G22 -> 22 | H16: =Drivers!H22 -> 4 | I16: =Drivers!I22 -> 46 | J16: =Drivers!J22 -> 33 | ... AL16: =Drivers!AL22
C17: =SUM(C15+C16) -> 42 | D17: =SUM(D15+D16) -> 46 | E17: =SUM(E15+E16) -> 50 | F17: =SUM(F15+F16) -> 70 | G17: =SUM(G15+G16) -> 92 | H17: =SUM(H15+H16) -> 30 | I17: =SUM(I15+I16) -> 102 | J17: =SUM(J15+J16) -> 74 | ... AL17: =SUM(AL15+AL16) -> 0
A18: =Drivers!AT16 -> Sasko | B18: =Drivers!AU16 -> Bell | C18: =Drivers!C20 -> 2 | D18: =Drivers!D20 -> 16 | E18: =Drivers!E20 -> 34 | F18: =Drivers!F20 -> 54 | G18: =Drivers!G20 -> 51 | H18: =Drivers!H20 -> 18 | I18: =Drivers!I20 -> 30 | J18: =Drivers!J20 -> 19 | ... AL18: =Drivers!AL20 | AM18: =SUM(C20:AL20) -> 968 | AN18: =RANK($AM$6:$AM$35,$AM$6:$AM$35,1>10) -> 7 | AO18: =AVERAGE(C20:AL20) -> 26.888889
B19: =Drivers!AU17 -> K. Busch | C19: =Drivers!C11 -> 29 | D19: =Drivers!D11 -> 7 | E19: =Drivers!E11 -> 25 | F19: =Drivers!F11 -> 20 | G19: =Drivers!G11 -> 9 | H19: =Drivers!H11 -> 16 | I19: =Drivers!I11 -> 13 | J19: =Drivers!J11 -> 12 | ... AL19: =Drivers!AL11
C20: =SUM(C18+C19) -> 31 | D20: =SUM(D18+D19) -> 23 | E20: =SUM(E18+E19) -> 59 | F20: =SUM(F18+F19) -> 74 | G20: =SUM(G18+G19) -> 60 | H20: =SUM(H18+H19) -> 34 | I20: =SUM(I18+I19) -> 43 | J20: =SUM(J18+J19) -> 31 | ... AL20: =SUM(AL18+AL19) -> 0
A21: =Drivers!AT19 -> Kyle (1) | B21: =Drivers!AU19 -> Byron | C21: =Drivers!C24 -> 25 | D21: =Drivers!D24 -> 25 | E21: =Drivers!E24 -> 26 | F21: =Drivers!F24 -> 32 | G21: =Drivers!G24 -> 49 | H21: =Drivers!H24 -> 34 | I21: =Drivers!I24 -> 47 | J21: =Drivers!J24 -> 7 | ... AL21: =Drivers!AL24 | AM21: =SUM(C23:AL23) -> 1421 | AN21: =RANK($AM$6:$AM$35,$AM$6:$AM$35,1>10) -> 4 | AO21: =AVERAGE(C23:AL23) -> 39.472222
B22: =Drivers!AU20 -> Gibbs | C22: =Drivers!C36 -> 3 | D22: =Drivers!D36 -> 14 | E22: =Drivers!E36 -> 5 | F22: =Drivers!F36 -> 0 | G22: =Drivers!G39 -> 39 | H22: =Drivers!H39 -> 33 | I22: =Drivers!I39 -> 49 | J22: =Drivers!J36 -> 1 | K22: =Drivers!K39 -> 38 | L22: =Drivers!L39 -> 3 | M22: =Drivers!M39 -> 8 | N22: =Drivers!N39 -> 42 | O22: =Drivers!O39 -> 53 | P22: =Drivers!P39 -> 24 | Q22: =Drivers!Q39 -> 21 | R22: =Drivers!R39 -> 36 | ... AL22: =Drivers!AL39
C23: =SUM(C21+C22) -> 28 | D23: =SUM(D21+D22) -> 39 | E23: =SUM(E21+E22) -> 31 | F23: =SUM(F21+F22) -> 32 | G23: =SUM(G21+G22) -> 88 | H23: =SUM(H21+H22) -> 67 | I23: =SUM(I21+I22) -> 96 | J23: =SUM(J21+J22) -> 8 | ... AL23: =SUM(AL21+AL22) -> 0
A24: =Drivers!AT22 -> Burrey (2) | B24: =Drivers!AU22 -> Blaney | C24: =Drivers!C15 -> 27 | D24: =Drivers!D15 -> 31 | E24: =Drivers!E15 -> 33 | F24: =Drivers!F15 -> 65 | G24: =Drivers!G15 -> 23 | H24: =Drivers!H15 -> 42 | I24: =Drivers!I15 -> 41 | J24: =Drivers!J15 -> 53 | ... AL24: =Drivers!AL15 | AM24: =SUM(C26:AL26) -> 1476 | AN24: =RANK($AM$6:$AM$35,$AM$6:$AM$35,1>10) -> 3 | AO24: =AVERAGE(C26:AL26) -> 41
B25: =Drivers!AU23 -> Hosevar | C25: =Drivers!C4 -> 17 | D25: =Drivers!D4 -> 34 | E25: =Drivers!E4 -> 13 | F25: =Drivers!F4 -> 10 | G25: =Drivers!G23 -> 41 | H25: =Drivers!H23 -> 10 | I25: =Drivers!I23 -> 1 | J25: =Drivers!J23 -> 30 | K25: =Drivers!K23 -> 39 | L25: =Drivers!L23 -> 1 | M25: =Drivers!M23 -> 28 | N25: =Drivers!N23 -> 9 | ... P25: =Drivers!P23 -> 10 | Q25: =Drivers!Q42 -> 45 | R25: =Drivers!R42 -> 21 | S25: =Drivers!S42 -> 27 | T25: =Drivers!T42 -> 33 | U25: =Drivers!U42 -> 15 | V25: =Drivers!V42 -> 39 | W25: =Drivers!W42 -> 35 | X25: =Drivers!X42 -> 40 | ... AL25: =Drivers!AL42
C26: =SUM(C24+C25) -> 44 | D26: =SUM(D24+D25) -> 65 | E26: =SUM(E24+E25) -> 46 | F26: =SUM(F24+F25) -> 75 | G26: =SUM(G24+G25) -> 64 | H26: =SUM(H24+H25) -> 52 | I26: =SUM(I24+I25) -> 42 | J26: =SUM(J24+J25) -> 83 | ... AL26: =SUM(AL24+AL25) -> 0
A27: =Drivers!AT25 -> 8 | B27: =Drivers!AU25 -> A | AM27: =SUM(C29:AL29) -> 0 | AN27: =RANK($AM$6:$AM$35,$AM$6:$AM$35,1>10) -> 8 | AO27: =AVERAGE(C29:AL29) -> 0
B28: =Drivers!AU26 -> B
C29: =SUM(C27+C28) -> 0 | D29: =SUM(D27+D28) -> 0 | E29: =SUM(E27+E28) -> 0 | F29: =SUM(F27+F28) -> 0 | G29: =SUM(G27+G28) -> 0 | H29: =SUM(H27+H28) -> 0 | I29: =SUM(I27+I28) -> 0 | J29: =SUM(J27+J28) -> 0 | ... AL29: =SUM(AL27+AL28) -> 0
A30: =Drivers!AT28 -> 9 | B30: =Drivers!AU28 -> A | AM30: =SUM(C32:AL32) -> 0 | AN30: =RANK($AM$6:$AM$35,$AM$6:$AM$35,1>10) -> 8 | AO30: =AVERAGE(C32:AL32) -> 0
B31: =Drivers!AU29 -> B
C32: =SUM(C30+C31) -> 0 | D32: =SUM(D30+D31) -> 0 | E32: =SUM(E30+E31) -> 0 | F32: =SUM(F30+F31) -> 0 | G32: =SUM(G30+G31) -> 0 | H32: =SUM(H30+H31) -> 0 | I32: =SUM(I30+I31) -> 0 | J32: =SUM(J30+J31) -> 0 | ... AL32: =SUM(AL30+AL31) -> 0
A33: =Drivers!AT31 -> 10 | B33: =Drivers!AU31 -> A | AM33: =SUM(C35:AL35) -> 0 | AN33: =RANK($AM$6:$AM$35,$AM$6:$AM$35,1>10) -> 8
B34: =Drivers!AU32 -> B
C35: =SUM(C33+C34) -> 0 | D35: =SUM(D33+D34) -> 0 | E35: =SUM(E33+E34) -> 0 | F35: =SUM(F33+F34) -> 0 | G35: =SUM(G33+G34) -> 0 | H35: =SUM(H33+H34) -> 0 | I35: =SUM(I33+I34) -> 0 | J35: =SUM(J33+J34) -> 0 | ... AL35: =SUM(AL33+AL34) -> 0

Sheet Leader Board Blue

Sheet Sheet1
